Workbook

Sheet Empresas Generadoras
B2: EMPRESAS GENERADORAS PARTICIPANTES DEL MERCADO DE CORTO PLAZO
B4: RAZÓN SOCIAL | C4: RUT | D4: SEGMENTO | E4: GIRO
B5: AASA Energía S.A. | C5: 76.596.827-5 | D5: PMGD, Generador | E5: Generación de Energía Eléctrica
B6: Abastible S.A. | C6: 91.806.000-6 | D6: PMGD | E6: GENERACION DE ENERGIA ELECTRICA EN OTRAS CENTRALES N.C.P.
B7: Acciona Energía Chile Holdings S.A. | C7: 76.437.712-5 | D7: Generador, PMGD | E7: Generación de Energía Eléctrica
B8: Acierta Energía SpA | C8: 77.333.033-6 | D8: PMGD | E8: Generación de Energía
B9: Aela Generación S.A. | C9: 76.489.426-K | D9: Transmisor Dedicado, Generador | E9: Generación de Energía Eléctrica
B10: AES Andes S.A. | C10: 94.272.000-9 | D10: Transmisor Dedicado, Generador, Transmisor Zonal | E10: Generación, Transmisión y Venta de Energía Eléctrica
B11: Aggreko Chile Limitada | C11: 76.625.330-K | D11: PMGD | E11: Generación de energía eléctrica en otras centrales N.C.P.
B12: Agrícola Ancalí Limitada | C12: 79.757.460-0 | D12: PMGD | E12: Agrícola, Lechería, Ganadería, Harás y Generación Eléctrica
B13: Agrosolar IV SpA | C13: 76.363.219-9 | D13: PMGD | E13: Generación en Otras Centrales N.C.P.
B14: Agrosolar V SpA | C14: 76.363.218-0 | D14: PMGD | E14: Generación en Otras Centrales N.C.P.
B15: Aguas Andinas S.A. | C15: 61.808.000-5 | D15: PMGD | E15: Servicios Sanitarios
... B695: Xue Solar SpA | C695: 76.466.222-9 | D695: PMGD | E695: Generación de Energía Eléctrica

Sheet Pagos Laterales
B2: Pagos Laterales Unitarios en Balances de Trasferencias de Energía en $/kWh de los últimos doce meses
B13: MES | C13: Retiros [MWh] | D13: Precio Estabilizado [mill. CLP] | E13: Sobrecosto Energía [mill. CLP] | F13: Sobrecosto P-D [mill. CLP] | G13: Reserva Hídrica [mill. CLP] | H13: SSCC [mill. CLP] | I13: TOTAL [mill. CLP] | J13: Precio Estabilizado Unitario [CLP/kWh] | K13: Sobrecosto Energía Unitario [CLP/kWh] | L13: Sobrecosto P-D Unitario [CLP/kWh] | M13: Reserva Hídrica Unitario [CLP/kWh] | N13: SSCC Unitario [CLP/kWh] | O13: TOTAL Unitario [CLP/kWh]
B14: 45658 | C14: 6907522.1 | D14: 34506.959 | E14: 21819.233 | F14: 839.62882 | G14: 0 | H14: 18219.523 | I14: =+SUM(D14:H14) -> 75385.344 | J14: =+D14*1000/$C14 -> 4.9955626 | K14: =+E14*1000/$C14 -> 3.1587641 | L14: =+F14*1000/$C14 -> 0.12155282 | M14: =+G14*1000/$C14 -> 0 | N14: =+H14*1000/$C14 -> 2.6376351 | O14: =+I14*1000/$C14 -> 10.913515
B15: 45689 | C15: 6216776.1 | D15: 23516.962 | E15: 21899.529 | F15: 1214.0559 | G15: 0 | H15: 15041.63 | I15: =+SUM(D15:H15) -> 61672.176 | J15: =+D15*1000/$C15 -> 3.7828227 | K15: =+E15*1000/$C15 -> 3.5226504 | L15: =+F15*1000/$C15 -> 0.19528706 | M15: =+G15*1000/$C15 -> 0 | N15: =+H15*1000/$C15 -> 2.4195225 | O15: =+I15*1000/$C15 -> 9.9202827
B16: 45717 | C16: 6817653.4 | D16: 19880.165 | E16: 22366.772 | F16: 849.96286 | G16: 0 | H16: 16573.524 | I16: =+SUM(D16:H16) -> 59670.424 | J16: =+D16*1000/$C16 -> 2.9159836 | K16: =+E16*1000/$C16 -> 3.2807142 | L16: =+F16*1000/$C16 -> 0.12467088 | M16: =+G16*1000/$C16 -> 0 | N16: =+H16*1000/$C16 -> 2.4309719 | O16: =+I16*1000/$C16 -> 8.7523405
B17: 45748 | C17: 6355658.8 | D17: 6389.6396 | E17: 17361.669 | F17: 742.26272 | G17: 0 | H17: 23342.1 | I17: =+SUM(D17:H17) -> 47835.672 | J17: =+D17*1000/$C17 -> 1.0053465 | K17: =+E17*1000/$C17 -> 2.7316868 | L17: =+F17*1000/$C17 -> 0.11678769 | M17: =+G17*1000/$C17 -> 0 | N17: =+H17*1000/$C17 -> 3.6726483 | O17: =+I17*1000/$C17 -> 7.5264694
B18: 45778 | C18: 6726678.7 | D18: 8363.1054 | E18: 12883.015 | F18: 547.60978 | G18: 0 | H18: 17373.384 | I18: =+SUM(D18:H18) -> 39167.114 | J18: =+D18*1000/$C18 -> 1.2432741 | K18: =+E18*1000/$C18 -> 1.9152119 | L18: =+F18*1000/$C18 -> 0.081408643 | M18: =+G18*1000/$C18 -> 0 | N18: =+H18*1000/$C18 -> 2.5827581 | O18: =+I18*1000/$C18 -> 5.8226528
B19: 45809 | C19: 6785598.5 | D19: -1682.1095 | E19: 16049.377 | F19: 420.23437 | G19: 0 | H19: 22875.225 | I19: =+SUM(D19:H19) -> 37662.727 | J19: =+D19*1000/$C19 -> -0.24789405 | K19: =+E19*1000/$C19 -> 2.3652117 | L19: =+F19*1000/$C19 -> 0.061930332 | M19: =+G19*1000/$C19 -> 0 | N19: =+H19*1000/$C19 -> 3.3711433 | O19: =+I19*1000/$C19 -> 5.5503913
B20: 45839 | C20: 6879473.8 | D20: 3422.1827 | E20: 15523.369 | F20: 834.07116 | G20: 0 | H20: 26642.669 | I20: =+SUM(D20:H20) -> 46422.292 | J20: =+D20*1000/$C20 -> 0.49744833 | K20: =+E20*1000/$C20 -> 2.2564762 | L20: =+F20*1000/$C20 -> 0.12124055 | M20: =+G20*1000/$C20 -> 0 | N20: =+H20*1000/$C20 -> 3.8727773 | O20: =+I20*1000/$C20 -> 6.7479423
B21: 45870 | C21: 6623523.9 | D21: 16466.25 | E21: 24744.639 | F21: 385.36841 | G21: 0 | H21: 22934.263 | I21: =+SUM(D21:H21) -> 64530.52 | J21: =+D21*1000/$C21 -> 2.4860256 | K21: =+E21*1000/$C21 -> 3.7358722 | L21: =+F21*1000/$C21 -> 0.05818178 | M21: =+G21*1000/$C21 -> 0 | N21: =+H21*1000/$C21 -> 3.462547 | O21: =+I21*1000/$C21 -> 9.7426266
B22: 45901 | C22: 6235722.2 | D22: 27057.87 | E22: 20684.308 | F22: 433.41587 | G22: 0 | H22: 21436.899 | I22: =+SUM(D22:H22) -> 69612.494 | J22: =+D22*1000/$C22 -> 4.3391718 | K22: =+E22*1000/$C22 -> 3.317067 | L22: =+F22*1000/$C22 -> 0.069505319 | M22: =+G22*1000/$C22 -> 0 | N22: =+H22*1000/$C22 -> 3.4377572 | O22: =+I22*1000/$C22 -> 11.163501
B23: 45931 | C23: 6501494 | D23: 35110.133 | E23: 20115.932 | F23: 468.9478 | G23: 0 | H23: 15817.907 | I23: =+SUM(D23:H23) -> 71512.92 | J23: =+D23*1000/$C23 -> 5.4003177 | K23: =+E23*1000/$C23 -> 3.0940476 | L23: =+F23*1000/$C23 -> 0.072129237 | M23: =+G23*1000/$C23 -> 0 | N23: =+H23*1000/$C23 -> 2.4329649 | O23: =+I23*1000/$C23 -> 10.99946
B24: 45962 | C24: 6476488.1 | D24: 37354.829 | E24: 22517.655 | F24: 547.81268 | G24: 0 | H24: 16172.505 | I24: =+SUM(D24:H24) -> 76592.801 | J24: =+D24*1000/$C24 -> 5.7677599 | K24: =+E24*1000/$C24 -> 3.4768311 | L24: =+F24*1000/$C24 -> 0.084584835 | M24: =+G24*1000/$C24 -> 0 | N24: =+H24*1000/$C24 -> 2.4971103 | O24: =+I24*1000/$C24 -> 11.826286
B25: 45992 | C25: 6992495.6 | D25: 38712.885 | E25: 23932.25 | F25: 699.81096 | G25: 0 | H25: 12942.711 | I25: =+SUM(D25:H25) -> 76287.656 | J25: =+D25*1000/$C25 -> 5.5363473 | K25: =+E25*1000/$C25 -> 3.4225621 | L25: =+F25*1000/$C25 -> 0.10008029 | M25: =+G25*1000/$C25 -> 0 | N25: =+H25*1000/$C25 -> 1.850943 | O25: =+I25*1000/$C25 -> 10.909933

Sheet Clientes Libres
B2: =+"Consumo de Clientes Libres en Balance de Transferencias de Energía (valores en MWh) en últimos 12 meses" -> Consumo de Clientes Libres en Balance de Transferencias de Energía (valores en MWh) en últimos 12 meses
B4: BARRA | C4: RUT CLIENTE | D4: NOMBRE O RAZÓN SOCIAL DEL CLIENTE | E4: SUMINISTRADOR | F4: CONECTADO A LA RED DE | G4: ene-25 | H4: feb-25 | I4: mar-25 | J4: abr-25 | K4: may-25 | L4: jun-25 | M4: jul-25 | N4: ago-25 | O4: sept-25 | P4: oct-25 | Q4: nov-25 | R4: dic-25
A5: BULEVAR RENTAS INMOBILIARIAS S.A. | B5: A.BLANCAS_____013 | C5: 76231235-2 | D5: BULEVAR RENTAS INMOBILIARIAS S.A. | E5: ENGIE | F5: COMPAÑÍA GENERAL DE ELECTRICIDAD S.A. | G5: 238.47221 | H5: 213.51893 | I5: 227.27544 | J5: 199.33756 | K5: 206.73139 | L5: 240.72241 | M5: 233.14583 | N5: 209.21579 | O5: 192.86457 | P5: 206.48778 | Q5: 204.07863 | R5: 245.27048
A6: ITI CHILE S A | B6: A.BLANCAS_____013 | C6: 76343170-3 | D6: ITI CHILE S A | E6: ABASTIBLE | F6: COMPAÑÍA GENERAL DE ELECTRICIDAD S.A. | G6: 173.4834 | H6: 175.9434 | I6: 193.455 | J6: 195.2526 | K6: 188.1414 | L6: 174.1236 | M6: 185.8158 | N6: 0
A7: CM MADERERA SPA | B7: A.BLANCAS_____013 | C7: 76682070-0 | D7: CM MADERERA SPA | E7: EMOAC | F7: COMPAÑÍA GENERAL DE ELECTRICIDAD S.A. | G7: 147.12208 | H7: 142.59564 | I7: 163.6506 | J7: 147.15251 | K7: 108.76004 | L7: 105.92224 | M7: 116.99053 | N7: 126.27187 | O7: 115.78594 | P7: 144.85153 | Q7: 141.77569 | R7: 151.92806
A8: SOLVAY PEROXIDOS DE LOS ANDES IND Y COM LTDA | B8: A.BLANCAS_____013 | C8: 76819130-1 | D8: SOLVAY PEROXIDOS DE LOS ANDES IND Y COM LTDA | E8: ENEL_GENERACION | F8: COMPAÑÍA GENERAL DE ELECTRICIDAD S.A. | G8: 1654.1887 | H8: 1303.5872 | I8: 1633.03 | J8: 1667.2958 | K8: 1607.6389 | L8: 1660.1453 | M8: 1704.6069 | N8: 1526.4678 | O8: 1392.8629 | P8: 1458.8173 | Q8: 1406.5455 | R8: 1448.0355
A9: ESSBIO S.A. | B9: A.BLANCAS_____013 | C9: 76833300-9 | D9: ESSBIO S.A. | E9: ENEL_GENERACION | F9: COMPAÑÍA GENERAL DE ELECTRICIDAD S.A. | G9: 278.01645 | H9: 245.4699 | I9: 264.83166 | J9: 245.45944 | K9: 241.41797 | L9: 233.17703 | M9: 240.06797 | N9: 253.32042 | O9: 211.7004 | P9: 230.23691 | Q9: 262.89375 | R9: 285.26211
A10: SODIMAC S.A. | B10: A.BLANCAS_____013 | C10: 96792430-K | D10: SODIMAC S.A. | E10: ENEL_GENERACION | F10: COMPAÑÍA GENERAL DE ELECTRICIDAD S.A. | G10: 108.06722 | H10: 88.491426 | I10: 115.45741 | J10: 138.25113 | K10: 154.60582 | L10: 148.35358 | M10: 155.35289 | N10: 141.60303 | O10: 118.4197 | P10: 118.32599 | Q10: 104.88056 | R10: 110.26093
A11: ORIZON S A | B11: A.BLANCAS_____013 | C11: 96929960-7 | D11: ORIZON S A | E11: EMOAC | F11: COMPAÑÍA GENERAL DE ELECTRICIDAD S.A. | G11: 1430.2599 | H11: 1472.1928 | I11: 1901.2739 | J11: 1367.2073 | K11: 1047.58 | L11: 892.03119 | M11: 722.89537 | N11: 721.35021 | O11: 154.85532 | P11: 434.90106 | Q11: 907.00144 | R11: 1672.2454
A12: AGUAS SAN PEDRO S A | B12: A.BLANCAS_____013 | C12: 99593190-7 | D12: AGUAS SAN PEDRO S A | E12: ENERGY_ASSET | F12: COMPAÑÍA GENERAL DE ELECTRICIDAD S.A. | G12: 189.74092 | H12: 171.63915 | I12: 187.0821 | J12: 170.3208 | K12: 180.64658 | L12: 164.3451 | M12: 179.22383 | N12: 0
A13: GENDARMERIA DE CHILE DIRECCION REGIONAL | B13: A.HOSPICIO____013 | C13: 61004002-0 | D13: GENDARMERIA DE CHILE DIRECCION REGIONAL | E13: ENEL_GENERACION | F13: COMPAÑÍA GENERAL DE ELECTRICIDAD S.A. | G13: 195.25408 | H13: 184.05912 | I13: 199.82928 | J13: 189.72716 | K13: 201.59468 | L13: 200.1664 | M13: 212.0104 | N13: 207.86696 | O13: 199.34656 | P13: 201.7078 | Q13: 191.32512 | R13: 192.20936
A14: ZONA FRANCA DE IQUIQUE S A | B14: A.HOSPICIO____013 | C14: 70285500-4 | D14: ZONA FRANCA DE IQUIQUE S A | E14: ABASTIBLE | F14: COMPAÑÍA GENERAL DE ELECTRICIDAD S.A. | K14: 127.8571 | L14: 120.32888 | M14: 122.57651 | N14: 122.72537 | O14: 122.64399 | P14: 123.70974 | Q14: 118.96119 | R14: 124.1444
A15: ZONA FRANCA DE IQUIQUE S A | B15: A.HOSPICIO____013 | C15: 70285500-4 | D15: ZONA FRANCA DE IQUIQUE S A | E15: ATRIA_ENERGIA | F15: COMPAÑÍA GENERAL DE ELECTRICIDAD S.A. | G15: 142.34479 | H15: 126.21105 | I15: 137.55346 | J15: 126.42857
A16: SR INMOBILIARIA S.A. | B16: A.HOSPICIO____013 | C16: 76002124-5 | D16: SR INMOBILIARIA S.A. | E16: EMOAC | F16: COMPAÑÍA GENERAL DE ELECTRICIDAD S.A. | G16: 101.2306 | H16: 99.469335 | I16: 112.38493 | J16: 91.697026 | K16: 82.054595 | L16: 74.084465 | M16: 75.861695 | N16: 75.94678 | O16: 72.55472 | P16: 82.01606 | Q16: 81.794125 | R16: 91.130375
A17: BRUENING INDUSTRIAL S.A. | B17: A.HOSPICIO____013 | C17: 76035258-6 | D17: BRUENING INDUSTRIAL S.A. | E17: ACIERTA_ENERGIA | F17: COMPAÑÍA GENERAL DE ELECTRICIDAD S.A. | G17: 122.63371 | H17: 101.29145 | I17: 145.93004 | J17: 104.63326
A18: BRUENING INDUSTRIAL S.A. | B18: A.HOSPICIO____013 | C18: 76035258-6 | D18: BRUENING INDUSTRIAL S.A. | E18: GR Power Chile SpA | F18: COMPAÑÍA GENERAL DE ELECTRICIDAD S.A. | K18: 103.0184 | L18: 97.854804 | M18: 111.29014 | N18: 102.62572 | O18: 121.68428 | P18: 136.11187 | Q18: 105.24307 | R18: 102.89931
A19: AGUAS DEL ALTIPLANO S.A. | B19: A.HOSPICIO____013 | C19: 76215634-2 | D19: AGUAS DEL ALTIPLANO S.A. | E19: ACCIONA_ENERGIA | F19: COMPAÑÍA GENERAL DE ELECTRICIDAD S.A. | I19: 30.44244 | J19: 30.1322 | K19: 31.15476 | L19: 26.73076 | M19: 29.29332 | N19: 30.21312 | O19: 28.9618 | P19: 33.45692 | Q19: 29.5456 | R19: 29.07436
A20: SOC COMERCIAL RECMETAL COMPANIA LIMITADA | B20: A.HOSPICIO____013 | C20: 77612130-4 | D20: SOC COMERCIAL RECMETAL COMPANIA LIMITADA | E20: ABASTIBLE | F20: COMPAÑÍA GENERAL DE ELECTRICIDAD S.A. | G20: 11.4331 | H20: 7.48573 | I20: 8.48519 | J20: 13.89234 | K20: 16.14291 | L20: 16.98067 | M20: 19.97674 | N20: 18.81222 | O20: 16.38224 | P20: 25.06672 | Q20: 21.45773 | R20: 8.88594
A21: POWER MAS SPA | B21: A.HOSPICIO____013 | C21: 78066213-1 | D21: POWER MAS SPA | E21: ABASTIBLE | F21: COMPAÑÍA GENERAL DE ELECTRICIDAD S.A. | R21: 55.123034
A22: CENCOSUD RETAIL S.A. | B22: A.HOSPICIO____013 | C22: 81201000-K | D22: CENCOSUD RETAIL S.A. | E22: AES_GENER | F22: COMPAÑÍA GENERAL DE ELECTRICIDAD S.A. | G22: 48.66288 | H22: 51.28956 | I22: 50.51018 | J22: 40.60126 | K22: 35.5222 | L22: 32.5052 | M22: 34.13578 | N22: 32.41518 | O22: 32.81754 | P22: 39.72542 | Q22: 42.5936 | R22: 45.297
A23: FINNING CHILE SA | B23: A.HOSPICIO____013 | C23: 91489000-4 | D23: FINNING CHILE SA | E23: ENEL_GENERACION | F23: COMPAÑÍA GENERAL DE ELECTRICIDAD S.A. | G23: 22.78486 | H23: 23.36054 | I23: 22.30648 | J23: 17.68704 | K23: 18.7992 | L23: 17.4426 | M23: 23.00032 | N23: 25.62434 | O23: 29.9544 | P23: 29.16158 | Q23: 26.24426 | R23: 27.1145
A24: KOMATSU CHILE S.A. | B24: A.HOSPICIO____013 | C24: 96843130-7 | D24: KOMATSU CHILE S.A. | E24: Innergex Energía Renovable SpA | F24: COMPAÑÍA GENERAL DE ELECTRICIDAD S.A. | G24: 38.65287 | H24: 34.435535 | I24: 38.339164 | J24: 34.453252 | K24: 35.592083 | L24: 34.209591 | M24: 34.391711 | N24: 32.59739 | O24: 32.313475 | P24: 34.585007 | Q24: 35.884904 | R24: 33.080864
A25: AGUAS DEL ALTIPLANO S.A. | B25: A.HOSPICIO____110 | C25: 76215634-2 | D25: AGUAS DEL ALTIPLANO S.A. | E25: ACCIONA_ENERGIA | F25: COMPAÑÍA GENERAL DE ELECTRICIDAD S.A. | G25: 31.4384 | H25: 25.56484
A26: POWER MAS SPA | B26: A.HOSPICIO____110 | C26: 78066213-1 | D26: POWER MAS SPA | E26: ABASTIBLE | F26: COMPAÑÍA GENERAL DE ELECTRICIDAD S.A. | Q26: 0 | R26: 0
A27: EMPRESA DE LOS FERROCARRILES DEL ESTADO | B27: A.JAHUEL______066 | C27: 61216000-7 | D27: EMPRESA DE LOS FERROCARRILES DEL ESTADO | E27: ENEL_GENERACION | F27: Cliente AT | G27: 302.8323 | H27: 0 | I27: 393.70193 | J27: 370.45034 | K27: 443.19874 | L27: 417.58704 | M27: 388.10595 | N27: 402.61309 | O27: 376.72742 | P27: 431.09221 | Q27: 335.98023 | R27: 451.14393
A28: COMUNIDAD EDIFICIO NERUDA | B28: A_DE_CORDOVA__013 | C28: 53300319-2 | D28: COMUNIDAD EDIFICIO NERUDA | E28: ACIERTA_ENERGIA | F28: ENEL DISTRIBUCIÓN CHILE S.A. | G28: 231.46715 | H28: 204.89369 | I28: 206.03389 | J28: 189.38444 | K28: 182.96742 | L28: 195.01145 | M28: 199.06715 | N28: 189.23665 | O28: 182.7261 | P28: 197.39483 | Q28: 189.42251 | R28: 200.59355
A29: EDIFICIO ALSACIA | B29: A_DE_CORDOVA__013 | C29: 53300841-0 | D29: EDIFICIO ALSACIA | E29: ENEL_GENERACION | F29: ENEL DISTRIBUCIÓN CHILE S.A. | G29: 183.1529 | H29: 157.4912 | I29: 174.2816 | J29: 161.7609 | K29: 170.4595 | L29: 181.784 | M29: 181.5629 | N29: 176.1545 | O29: 162.7237 | P29: 174.0353 | Q29: 171.1129 | R29: 191.7155
A30: EDIFICIO ISIDORA GOYENECHEA 3520 | B30: A_DE_CORDOVA__013 | C30: 53301881-5 | D30: EDIFICIO ISIDORA GOYENECHEA 3520 | E30: IMELSA_ENERGIA | F30: ENEL DISTRIBUCIÓN CHILE S.A. | G30: 144.5192 | H30: 130.8874 | I30: 130.6174 | J30: 112.2513 | K30: 99.0645 | L30: 94.8601 | M30: 109.3176 | N30: 104.4233 | O30: 111.9178 | P30: 120.6797 | Q30: 116.4133 | R30: 140.317
A31: COMUNIDAD EDIFICIO MISTRAL 615 | B31: A_DE_CORDOVA__013 | C31: 53303284-2 | D31: COMUNIDAD EDIFICIO MISTRAL 615 | E31: EMOAC | F31: ENEL DISTRIBUCIÓN CHILE S.A. | O31: 157.31414 | P31: 183.06472 | Q31: 176.47933 | R31: 188.84337
A32: COMUNIDAD EDIFICIO MISTRAL 615 | B32: A_DE_CORDOVA__013 | C32: 53303284-2 | D32: COMUNIDAD EDIFICIO MISTRAL 615 | E32: ENEL_GENERACION | F32: ENEL DISTRIBUCIÓN CHILE S.A. | G32: 221.37481 | H32: 192.46991 | I32: 207.3247 | J32: 171.36478 | K32: 171.20083 | L32: 189.09439 | M32: 185.39596 | N32: 165.7855
A33: COMUNIDAD EDIFICIO PARQUE ARAUCANO | B33: A_DE_CORDOVA__013 | C33: 53305293-2 | D33: COMUNIDAD EDIFICIO PARQUE ARAUCANO | E33: ENEL_GENERACION | F33: ENEL DISTRIBUCIÓN CHILE S.A. | G33: 313.14985 | H33: 273.82389 | I33: 297.69389 | J33: 260.79292 | K33: 246.71413 | L33: 243.77791 | M33: 266.24145 | N33: 244.4328 | O33: 231.91202 | P33: 266.33809 | Q33: 261.37481 | R33: 276.49638
A34: EDIFICIO BURGOS | B34: A_DE_CORDOVA__013 | C34: 53306785-9 | D34: EDIFICIO BURGOS | E34: IMELSA_ENERGIA | F34: ENEL DISTRIBUCIÓN CHILE S.A. | G34: 410.90246 | H34: 362.26158 | I34: 378.55075 | J34: 342.8039 | K34: 335.03773 | L34: 352.59286 | M34: 356.69693 | N34: 337.44519 | O34: 319.93454 | P34: 346.63802 | Q34: 311.05139 | R34: 346.38765
A35: COMUNIDAD EDIFICIO MATTA 530 | B35: A_DE_CORDOVA__013 | C35: 53307190-2 | D35: COMUNIDAD EDIFICIO MATTA 530 | E35: IMELSA_ENERGIA | F35: ENEL DISTRIBUCIÓN CHILE S.A. | G35: 309.1704 | H35: 268.63945 | I35: 286.34371 | J35: 256.79862 | K35: 244.6416 | L35: 251.97214 | M35: 259.22255 | N35: 259.826 | O35: 230.99026 | P35: 256.51205 | Q35: 260.01294 | R35: 289.29874
A36: EDIFICIO ISIDORA MAGDALENA | B36: A_DE_CORDOVA__013 | C36: 53307401-4 | D36: EDIFICIO ISIDORA MAGDALENA | E36: IMELSA_ENERGIA | F36: ENEL DISTRIBUCIÓN CHILE S.A. | G36: 287.522 | H36: 247.666 | I36: 268.862 | J36: 227.867 | K36: 231.815 | L36: 243.617 | M36: 247.254 | N36: 232.879 | O36: 220.558 | P36: 242.145 | Q36: 247.185 | R36: 267.903
A37: COMUNIDAD EDIFICIO APOQUINDO 3910 | B37: A_DE_CORDOVA__013 | C37: 53308832-5 | D37: COMUNIDAD EDIFICIO APOQUINDO 3910 | E37: ENEL_GENERACION | F37: ENEL DISTRIBUCIÓN CHILE S.A. | G37: 69.151 | H37: 60.877 | I37: 60.839 | J37: 47.162 | K37: 47.614 | L37: 57.362 | M37: 56.388 | N37: 49.782 | O37: 47.367 | P37: 53.116 | Q37: 55.832 | R37: 63.197
A38: EDIFICIO GOLF 82 | B38: A_DE_CORDOVA__013 | C38: 53313019-4 | D38: EDIFICIO GOLF 82 | E38: IMELSA_ENERGIA | F38: ENEL DISTRIBUCIÓN CHILE S.A. | G38: 71.627 | H38: 58.443 | I38: 62.017 | J38: 48.878 | K38: 51.581 | L38: 64.938 | M38: 67.389 | N38: 60.589 | O38: 54.475 | P38: 60.522 | Q38: 57.462 | R38: 63.644
A39: EDIFICIO MAGDALENA NORTE | B39: A_DE_CORDOVA__013 | C39: 53313325-8 | D39: EDIFICIO MAGDALENA NORTE | E39: ACIERTA_ENERGIA | F39: ENEL DISTRIBUCIÓN CHILE S.A. | G39: 124.336 | H39: 105.782 | I39: 111.261 | J39: 93.258 | K39: 98.323 | L39: 113.448 | M39: 118.066 | N39: 105.181 | O39: 97.067 | P39: 99.348 | Q39: 99.692 | R39: 114.107
A40: EDIFICIO PARQUE ANDINO | B40: A_DE_CORDOVA__013 | C40: 53313950-7 | D40: EDIFICIO PARQUE ANDINO | E40: ENEL_GENERACION | F40: ENEL DISTRIBUCIÓN CHILE S.A. | G40: 360.737 | H40: 329.751 | I40: 357.208 | J40: 290.74 | K40: 278.788 | L40: 290.574 | M40: 299.538 | N40: 285.792 | O40: 276.488 | P40: 314.779 | Q40: 304.061 | R40: 310.827
A41: COMUNIDAD EDIFICIO ARRAU | B41: A_DE_CORDOVA__013 | C41: 53315032-2 | D41: COMUNIDAD EDIFICIO ARRAU | E41: ENEL_GENERACION | F41: ENEL DISTRIBUCIÓN CHILE S.A. | G41: 348.293 | H41: 322.992 | I41: 333.113 | J41: 298.637 | K41: 271.344 | L41: 266.238 | M41: 291.714 | N41: 280.621 | O41: 277.092 | P41: 317.364 | Q41: 305.518 | R41: 338.262
A42: COMUNIDAD EDIFICIO PARQUE SUR | B42: A_DE_CORDOVA__013 | C42: 53315212-0 | D42: COMUNIDAD EDIFICIO PARQUE SUR | E42: ENEL_GENERACION | F42: ENEL DISTRIBUCIÓN CHILE S.A. | G42: 325.79362 | H42: 286.90929 | I42: 300.74592 | J42: 265.44652 | K42: 265.54037 | L42: 264.78978 | M42: 273.07198 | N42: 253.76081 | O42: 243.73316 | P42: 275.69986 | Q42: 270.21008 | R42: 295.44905
...

Sheet Clientes Potencialmente Libres
B2: Clientes Regulados Potencialmente Libres a Diciembre 2025
B4: (Información entregada por las distribuidoras en el Catastro de Clientes Dx al que se refiere el artículo 1-17 de la Norma Técnica de Calidad de Servicio para Sistemas de Distribución)
B6: CONCESIONARIA | C6: CALIDAD JURIDICA | D6: TIPO_CLIENTE | E6: CLIENTE ID | F6: TIPO CONSUMO | G6: NOMBRE O RAZÓN SOCIAL DEL CLIENTE | H6: TIPO EMPALME | I6: TENSIÓN | J6: S/E PRIMARIA | K6: ALIMENTADOR | L6: POTENCIA_CONECTADA [kW] | M6: CONSUMO PROMEDIO ÚLTIMOS 12 MESES [kWh]
B7: CEC | D7: Cliente Potencialmente Libre | E7: 76145033 | F7: Industrial | G7: AGRICOLA EL MILAGRO LTDA. | H7: Red Aerea | I7: 0.38kV | J7: CURICO | K7: LOS NICHES | L7: 363 | M7: 7500
B8: CEC | D8: Cliente Potencialmente Libre | E8: 76145033 | F8: Industrial | G8: AGRICOLA EL MILAGRO LTDA. | H8: Red Aerea | I8: 0.38kV | J8: CURICO | K8: LOS NICHES | L8: 363 | M8: 1950
B9: CEC | D9: Cliente Potencialmente Libre | E9: 76145033 | F9: Industrial | G9: AGRICOLA EL MILAGRO LTDA. | H9: Red Aerea | I9: 0.38kV | J9: CURICO | K9: LOS NICHES | L9: 363 | M9: 2550
B10: CEC | D10: Cliente Potencialmente Libre | E10: 76152190 | F10: Industrial | G10: AGRICOLA EL PRINCIPAL LTDA | H10: Red Aerea | I10: 0.22kV | J10: CURICO | K10: LA OBRA | L10: 450 | M10: 3500
B11: CEC | D11: Cliente Potencialmente Libre | E11: 76152190 | F11: Industrial | G11: AGRICOLA EL PRINCIPAL LTDA | H11: Red Aerea | I11: 0.22kV | J11: CURICO | K11: LA OBRA | L11: 450 | M11: 3500
B12: CEC | D12: Cliente Potencialmente Libre | E12: 76152190 | F12: Industrial | G12: AGRICOLA EL PRINCIPAL LTDA | H12: Red Aerea | I12: 0.22kV | J12: CURICO | K12: LA OBRA | L12: 450 | M12: 2940
B13: CEC | D13: Cliente Potencialmente Libre | E13: 77980980 | F13: Industrial | G13: AGRICOLA GEOAGRO LIMITADA | H13: Red Aerea | I13: 0.38kV | J13: QUINTAY | K13: MORZA | L13: 451 | M13: 840
B14: CEC | D14: Cliente Potencialmente Libre | E14: 77980980 | F14: Industrial | G14: AGRICOLA GEOAGRO LIMITADA | H14: Red Aerea | I14: 0.38kV | J14: QUINTAY | K14: MORZA | L14: 451 | M14: 700
B15: CEC | D15: Cliente Potencialmente Libre | E15: 77980980 | F15: Industrial | G15: AGRICOLA GEOAGRO LIMITADA | H15: Red Aerea | I15: 0.38kV | J15: QUINTAY | K15: MORZA | L15: 451 | M15: 700
B16: CEC | D16: Cliente Potencialmente Libre | E16: 76599971 | F16: Agricola | G16: AGRICOLA RIBERA NORTE SPA | H16: Red Aerea | I16: 0.38kV | J16: TENO | K16: LA LAGUNA | L16: 850 | M16: 0
B17: CEC | D17: Cliente Potencialmente Libre | E17: 76599971 | F17: Agricola | G17: AGRICOLA RIBERA NORTE SPA | H17: Red Aerea | I17: 0.38kV | J17: TENO | K17: LA LAGUNA | L17: 850 | M17: 0
B18: CEC | D18: Cliente Potencialmente Libre | E18: 76599971 | F18: Agricola | G18: AGRICOLA RIBERA NORTE SPA | H18: Red Aerea | I18: 0.38kV | J18: TENO | K18: LA LAGUNA | L18: 850 | M18: 0
... B161: CEC | D161: Cliente Potencialmente Libre | E161: 77454128 | F161: Industrial | G161: YOLO GROUP SPA | H161: Red Aerea | I161: 0.22kV | J161: TENO | K161: LOS QUEÑES | L161: 728.7 | M161: 36929
B162: CGE | C162: Persona Jurídica | D162: Cliente Potencialmente Libre | E162: 78040440 | F162: Industrial | G162: PROEX SPA | H162: Red Aerea | I162: 15kV | J162: SAN FRANCISCO DE MOSTAZAL | K162: PILAY | L162: 389.7 | M162: 0
B163: CGE | C163: Persona Jurídica | D163: Cliente Potencialmente Libre | E163: 96858420 | F163: Agricola | G163: SOHO SPA | H163: Red Aerea | I163: 11kV | J163: HOSPITAL | K163: CHAMPA | L163: 498 | M163: 18760
B164: CGE | C164: Persona Jurídica | D164: Cliente Potencialmente Libre | E164: 65287570 | F164: Municipal | G164: 1RA BRIGADA ACORAZADA CORACEROS | H164: Red Aerea | I164: 0.38kV | J164: QUIANI | K164: CHUNGARA | L164: 592.3 | M164: 45000
B165: CGE | C165: Persona Jurídica | D165: Cliente Potencialmente Libre | E165: 65283230 | F165: Comercial | G165: 2 BRIGADA ACORAZADA CAZADORES | H165: Red Aerea | I165: 0.38kV | J165: POZO ALMONTE | K165: PAMPINO | L165: 592.3 | M165: 101400
B166: CGE | C166: Persona Jurídica | D166: Cliente Potencialmente Libre | E166: 65283230 | F166: Industrial | G166: 2 BRIGADA ACORAZADA CAZADORES | H166: Red Aerea | I166: 0.38kV | J166: POZO ALMONTE | K166: PAMPINO | L166: 329.1 | M166: 53880
B167: CGE | C167: Persona Jurídica | D167: Cliente Potencialmente Libre | E167: 76833720 | F167: Comercial | G167: ABARROTES ECONOMICOS LTDA. | H167: Red Aerea | I167: 0.38kV | J167: SAN CARLOS | K167: VIOLETA PARRA | L167: 329.1 | M167: 51000
B168: CGE | C168: Persona Jurídica | D168: Cliente Potencialmente Libre | E168: 76833720 | F168: Comercial | G168: ABARROTES ECONOMICOS LTDA. | H168: Red Aerea | I168: 15kV | J168: PERALES | K168: GOLONDRINAS | L168: 415.7 | M168: 35550
B169: CGE | C169: Persona Jurídica | D169: Cliente Potencialmente Libre | E169: 76833720 | F169: Comercial | G169: ABARROTES ECONOMICOS LTDA. | H169: Red Aerea | I169: 15kV | J169: PERALES | K169: GOLONDRINAS | L169: 415.7 | M169: 33900
B170: CGE | C170: Persona Jurídica | D170: Cliente Potencialmente Libre | E170: 76833720 | F170: Comercial | G170: ABARROTES ECONOMICOS LTDA. | H170: Red Aerea | I170: 12 kV | J170: SANTA ROSA SUR | K170: LO MARTINEZ | L170: 311.8 | M170: 0
B171: CGE | C171: Persona Jurídica | D171: Cliente Potencialmente Libre | E171: 76833720 | F171: Residencial | G171: ABARROTES ECONOMICOS LTDA. | H171: Red Aerea | I171: 15kV | J171: CHIGUAYANTE | K171: HUALQUI | L171: 311.8 | M171: 36000
B172: CGE | C172: Persona Jurídica | D172: Cliente Potencialmente Libre | E172: 76833720 | F172: Comercial | G172: ABARROTES ECONOMICOS LTDA. | H172: Red Aerea | I172: 0.38kV | J172: CONSTITUCION | K172: FALUCHO | L172: 329.1 | M172: 51360
B173: CGE | C173: Persona Jurídica | D173: Cliente Potencialmente Libre | E173: 76833720 | F173: Comercial | G173: ABARROTES ECONOMICOS LTDA. | H173: Red Aerea | I173: 15kV | J173: LAS ENCINAS | K173: BOTROLHUE | L173: 389.7 | M173: 32700
... B223: CGE | C223: Persona Jurídica | D223: Cliente Potencialmente Libre | E223: 96549220 | F223: Comercial | G223: AGRI Y COMER STA CECILIA S.A. | H223: Red Aerea | I223: 15kV | J223: MANSO DE VELASCO | K223: ALEMANIA | L223: 311.8 | M223: 8700
B224: CGE | C224: Persona Jurídica | D224: Cliente Potencialmente Libre | E224: 78058290 | F224: Agricola | G224: AGRIC LA CABAÑA DOS LTDA | H224: Red Aerea | I224: 15kV | L224: 311.8 | M224: 50778
B225: CGE | C225: Persona Jurídica | D225: Cliente Potencialmente Libre | E225: 77865980 | F225: Agricola | G225: AGRIC STA CRISTINA LTDA | H225: Red Aerea | I225: 15kV | J225: CHUMAQUITO | K225: SAN ISIDRO | L225: 415.7 | M225: 9450
B226: CGE | C226: Persona Jurídica | D226: Cliente Potencialmente Libre | E226: 76069280 | F226: Agricola | G226: AGRIC Y EXP.TIERRA PURA LIMITADA | H226: Red Aerea | I226: 23kV | J226: INCAHUASI | K226: LA HIGUERA | L226: 637.4 | M226: 1920
B227: CGE | C227: Persona Jurídica | D227: Cliente Potencialmente Libre | E227: 89139200 | F227: Comercial | G227: AGRIC Y FRUTICOLA DEL CENTRO LTDA | H227: Red Aerea | I227: 0.38kV | J227: VILLA PRAT | K227: PETEROA | L227: 329.1 | M227: 16800
B228: CGE | C228: Persona Jurídica | D228: Cliente Potencialmente Libre | E228: 89139200 | F228: Industrial | G228: AGRIC Y FRUTICOLA DEL CENTRO LTDA | H228: Red Aerea | I228: 13kV | J228: CURICO | K228: ZAPALLAR | L228: 731.6 | M228: 1920
B229: CGE | C229: Persona Jurídica | D229: Cliente Potencialmente Libre | E229: 77587720 | F229: Agricola | G229: AGRIC. EL BUEN PASTOR LTDA | H229: Red Aerea | I229: 15kV | J229: COLCHAGUA | K229: TINGUIRIRICA | L229: 1636.7 | M229: 23775
B230: CGE | C230: Persona Jurídica | D230: Cliente Potencialmente Libre | E230: 77373640 | F230: Agricola | G230: AGRÍC. FORESTAL Y GANADERA STA INES DE | H230: Red Aerea | I230: 15kV | J230: LEYDA | K230: EL TURCO | L230: 311.8 | M230: 69720
B231: CGE | C231: Persona Jurídica | D231: Cliente Potencialmente Libre | E231: 77373640 | F231: Agricola | G231: AGRÍC. FORESTAL Y GANADERA STA INES DE | H231: Red Aerea | I231: 15kV | J231: LEYDA | K231: EL TURCO | L231: 311.8 | M231: 95480
B232: CGE | C232: Persona Jurídica | D232: Cliente Potencialmente Libre | E232: 78750450 | F232: Agricola | G232: AGRIC. GREEN SEED LTDA. | H232: Red Aerea | I232: 0.38kV | J232: SAN FRANCISCO DE MOSTAZAL | K232: SANTA BLANCA | L232: 329.1 | M232: 6600
B233: CGE | C233: Persona Jurídica | D233: Cliente Potencialmente Libre | E233: 84629300 | F233: Agricola | G233: AGRICOLA AGROBOSQUES SAN ISIDRO SA | H233: Red Aerea | I233: 15kV | J233: GRANEROS | K233: BERRIOS | L233: 415.7 | M233: 9600
B234: CGE | C234: Persona Jurídica | D234: Cliente Potencialmente Libre | E234: 84629300 | F234: Agricola | G234: AGRICOLA AGROBOSQUES SAN ISIDRO SA | H234: Red Aerea | I234: 15kV | J234: GRANEROS | K234: BERRIOS | L234: 415.7 | M234: 23400
...

Sheet Escondida
A2: =+"Consumo de Clientes Libres en Balance de Transferencias de Energía (valores en MWh) en últimos 12 meses" -> Consumo de Clientes Libres en Balance de Transferencias de Energía (valores en MWh) en últimos 12 meses
B4: BARRA | C4: RUT CLIENTE | D4: NOMBRE O RAZÓN SOCIAL DEL CLIENTE | E4: SUMINISTRADOR | F4: CONECTADO A LA RED DE | G4: ene-25 | H4: feb-25 | I4: mar-25 | J4: abr-25 | K4: may-25 | L4: jun-25 | M4: jul-25 | N4: ago-25 | O4: sept-25 | P4: oct-25 | Q4: nov-25 | R4: dic-25 | T4: TOTAL
A5: {=_xlfn._xlws.FILTER('Clientes Libres'!$A$5:$R$5414,'Clientes Libres'!$A$5:$A$5414="MINERA ESCONDIDA LIMITADA")} -> MINERA ESCONDIDA LIMITADA | B5: BOMBEO2_______004 | C5: 79587210-8 | D5: MINERA ESCONDIDA LIMITADA | E5: COLBUN | F5: Cliente AT | G5: 460.29815 | H5: 393.69743 | I5: 455.07673 | J5: 544.58101 | K5: 608.62649 | L5: 442.8749 | M5: 604.66289 | N5: 573.45262 | O5: 527.31077 | P5: 536.18789 | Q5: 367.59233 | R5: 357.50604 | T5: =SUM(G5:R5) -> 5871.8673
A6: MINERA ESCONDIDA LIMITADA | B6: BOMBEO2_______004 | C6: 79587210-8 | D6: MINERA ESCONDIDA LIMITADA | E6: ENEL_GENERACION | F6: Cliente AT | G6: 499.73655 | H6: 393.63644 | I6: 458.99249 | J6: 544.48846 | K6: 608.3669 | L6: 442.11346 | M6: 604.55423 | N6: 573.42608 | O6: 527.27819 | P6: 536.18789 | Q6: 367.59233 | R6: 320.10306 | T6: =SUM(G6:R6) -> 5876.4761
A7: MINERA ESCONDIDA LIMITADA | B7: BOMBEO2_______004 | C7: 79587210-8 | D7: MINERA ESCONDIDA LIMITADA | E7: TAMAKAYA_ENERGIA | F7: Cliente AT | G7: 0 | H7: 0 | I7: 3.960167 | J7: 0 | K7: 0 | L7: 0 | M7: 0 | N7: 0.026543 | O7: 0.032583 | P7: 0 | Q7: 0 | R7: 249.35575 | T7: =SUM(G7:R7) -> 253.37505
A8: MINERA ESCONDIDA LIMITADA | B8: BOMBEO3_______004 | C8: 79587210-8 | D8: MINERA ESCONDIDA LIMITADA | E8: COLBUN | F8: Cliente AT | G8: 557.59304 | H8: 511.68874 | I8: 530.61945 | J8: 610.34706 | K8: 588.06084 | L8: 424.45912 | M8: 596.63574 | N8: 678.24684 | O8: 659.43974 | P8: 635.00167 | Q8: 481.69758 | R8: 367.1744 | T8: =SUM(G8:R8) -> 6640.9642
A9: MINERA ESCONDIDA LIMITADA | B9: BOMBEO3_______004 | C9: 79587210-8 | D9: MINERA ESCONDIDA LIMITADA | E9: ENEL_GENERACION | F9: Cliente AT | G9: 605.90996 | H9: 511.61375 | I9: 537.3255 | J9: 610.25985 | K9: 587.81773 | L9: 423.70488 | M9: 596.5159 | N9: 678.22042 | O9: 659.40725 | P9: 635.00167 | Q9: 481.69758 | R9: 322.04701 | T9: =SUM(G9:R9) -> 6649.5215
A10: MINERA ESCONDIDA LIMITADA | B10: BOMBEO3_______004 | C10: 79587210-8 | D10: MINERA ESCONDIDA LIMITADA | E10: TAMAKAYA_ENERGIA | F10: Cliente AT | G10: 0 | H10: 0 | I10: 6.766437 | J10: 0 | K10: 0 | L10: 0 | M10: 0 | N10: 0.026418 | O10: 0.03249 | P10: 0 | Q10: 0 | R10: 282.92906 | T10: =SUM(G10:R10) -> 289.7544
A11: MINERA ESCONDIDA LIMITADA | B11: BOMBEO4_______004 | C11: 79587210-8 | D11: MINERA ESCONDIDA LIMITADA | E11: COLBUN | F11: Cliente AT | G11: 581.28291 | H11: 494.92721 | I11: 537.84914 | J11: 633.89743 | K11: 612.67975 | L11: 428.98917 | M11: 590.02888 | N11: 599.63951 | O11: 589.31599 | P11: 589.06608 | Q11: 443.28045 | R11: 330.67957 | T11: =SUM(G11:R11) -> 6431.6361
A12: MINERA ESCONDIDA LIMITADA | B12: BOMBEO4_______004 | C12: 79587210-8 | D12: MINERA ESCONDIDA LIMITADA | E12: ENEL_GENERACION | F12: Cliente AT | G12: 631.63555 | H12: 494.85621 | I12: 544.80693 | J12: 633.80362 | K12: 612.4277 | L12: 428.20497 | M12: 589.90588 | N12: 599.61667 | O12: 589.28819 | P12: 589.06608 | Q12: 443.28045 | R12: 289.09101 | T12: =SUM(G12:R12) -> 6445.9833
A13: MINERA ESCONDIDA LIMITADA | B13: BOMBEO4_______004 | C13: 79587210-8 | D13: MINERA ESCONDIDA LIMITADA | E13: TAMAKAYA_ENERGIA | F13: Cliente AT | G13: 0 | H13: 0 | I13: 7.018365 | J13: 0 | K13: 0 | L13: 0 | M13: 0 | N13: 0.022843 | O13: 0.027804 | P13: 0 | Q13: 0 | R13: 266.55605 | T13: =SUM(G13:R13) -> 273.62507
A14: MINERA ESCONDIDA LIMITADA | B14: CHIMBORAZO____220 | C14: 79587210-8 | D14: MINERA ESCONDIDA LIMITADA | E14: COLBUN | F14: Cliente AT | G14: 13086.623 | H14: 13239.782 | I14: 13681.745 | J14: 14402.74 | K14: 15258.894 | L14: 13559.136 | M14: 12532.263 | N14: 13184.597 | O14: 13603.579 | P14: 14103.642 | Q14: 12527.713 | R14: 12927.946 | T14: =SUM(G14:R14) -> 162108.66
A15: MINERA ESCONDIDA LIMITADA | B15: CHIMBORAZO____220 | C15: 79587210-8 | D15: MINERA ESCONDIDA LIMITADA | E15: ENEL_GENERACION | F15: Cliente AT | G15: 14182.392 | H15: 13238.252 | I15: 13818.423 | J15: 14400.65 | K15: 15253.17 | L15: 13540.831 | M15: 12529.673 | N15: 13184.068 | O15: 13602.913 | P15: 14103.642 | Q15: 12527.713 | R15: 10980.383 | T15: =SUM(G15:R15) -> 161362.11
A16: MINERA ESCONDIDA LIMITADA | B16: CHIMBORAZO____220 | C16: 79587210-8 | D16: MINERA ESCONDIDA LIMITADA | E16: TAMAKAYA_ENERGIA | F16: Cliente AT | G16: 0 | H16: 0 | I16: 138.01374 | J16: 0 | K16: 0 | L16: 0 | M16: 0 | N16: 0.52921 | O16: 0.666506 | P16: 0 | Q16: 0 | R16: 7482.7234 | T16: =SUM(G16:R16) -> 7621.9329
A17: MINERA ESCONDIDA LIMITADA | B17: COLOSO________220 | C17: 79587210-8 | D17: MINERA ESCONDIDA LIMITADA | E17: COLBUN | F17: Cliente AT | G17: 27899.808 | H17: 28132.644 | I17: 29700.716 | J17: 31341.929 | K17: 32580.186 | L17: 28704.892 | M17: 26995.389 | N17: 28625.258 | O17: 29135.405 | P17: 30085.344 | Q17: 26910.737 | R17: 25671.884 | T17: =SUM(G17:R17) -> 345784.19
... A38: MINERA ESCONDIDA LIMITADA | B38: SUR___________110 | C38: 79587210-8 | D38: MINERA ESCONDIDA LIMITADA | E38: AES_GENER | F38: COMPAÑÍA GENERAL DE ELECTRICIDAD S.A. | G38: 0 | H38: 0 | I38: 0 | J38: 0 | K38: 0 | L38: 0 | M38: 0 | N38: 0 | O38: 0 | P38: 0 | Q38: 0 | R38: 0 | T38: =SUM(G38:R38) -> 0
G40: =SUM(G5:G38) -> 448230.51 | H40: =SUM(H5:H38) -> 431099.76 | I40: =SUM(I5:I38) -> 470673.5 | J40: =SUM(J5:J38) -> 491152.01 | K40: =SUM(K5:K38) -> 509202.61 | L40: =SUM(L5:L38) -> 461526.09 | M40: =SUM(M5:M38) -> 458204.33 | N40: =SUM(N5:N38) -> 482092.66 | ... R40: =SUM(R5:R38) -> 496969.65 | T40: =SUM(T5:T38) -> 5629455

Sheet Locations
B1: Barra | C1: Tipo | D1: ene-25 | E1: feb-25 | F1: mar-25 | G1: abr-25 | H1: may-25 | I1: jun-25 | J1: jul-25 | K1: ago-25 | L1: sept-25 | M1: oct-25 | N1: nov-25 | O1: dic-25 | P1: TOTAL
B2: BOMBEO2_______004 | C2: Bombeo | D2: =SUMIF(Escondida!$B$5:$B$38,Locations!$B2,Escondida!G$5:G$38) -> 960.03469 | E2: =SUMIF(Escondida!$B$5:$B$38,Locations!$B2,Escondida!H$5:H$38) -> 787.33388 | F2: =SUMIF(Escondida!$B$5:$B$38,Locations!$B2,Escondida!I$5:I$38) -> 918.02939 | G2: =SUMIF(Escondida!$B$5:$B$38,Locations!$B2,Escondida!J$5:J$38) -> 1089.0695 | H2: =SUMIF(Escondida!$B$5:$B$38,Locations!$B2,Escondida!K$5:K$38) -> 1216.9934 | I2: =SUMIF(Escondida!$B$5:$B$38,Locations!$B2,Escondida!L$5:L$38) -> 884.98836 | J2: =SUMIF(Escondida!$B$5:$B$38,Locations!$B2,Escondida!M$5:M$38) -> 1209.2171 | K2: =SUMIF(Escondida!$B$5:$B$38,Locations!$B2,Escondida!N$5:N$38) -> 1146.9052 | ... O2: =SUMIF(Escondida!$B$5:$B$38,Locations!$B2,Escondida!R$5:R$38) -> 926.96485 | P2: =SUM(D2:O2) -> 12001.718
B3: BOMBEO3_______004 | C3: Bombeo | D3: =SUMIF(Escondida!$B$5:$B$38,Locations!$B3,Escondida!G$5:G$38) -> 1163.503 | E3: =SUMIF(Escondida!$B$5:$B$38,Locations!$B3,Escondida!H$5:H$38) -> 1023.3025 | F3: =SUMIF(Escondida!$B$5:$B$38,Locations!$B3,Escondida!I$5:I$38) -> 1074.7114 | G3: =SUMIF(Escondida!$B$5:$B$38,Locations!$B3,Escondida!J$5:J$38) -> 1220.6069 | H3: =SUMIF(Escondida!$B$5:$B$38,Locations!$B3,Escondida!K$5:K$38) -> 1175.8786 | I3: =SUMIF(Escondida!$B$5:$B$38,Locations!$B3,Escondida!L$5:L$38) -> 848.164 | J3: =SUMIF(Escondida!$B$5:$B$38,Locations!$B3,Escondida!M$5:M$38) -> 1193.1516 | K3: =SUMIF(Escondida!$B$5:$B$38,Locations!$B3,Escondida!N$5:N$38) -> 1356.4937 | ... O3: =SUMIF(Escondida!$B$5:$B$38,Locations!$B3,Escondida!R$5:R$38) -> 972.15047 | P3: =SUM(D3:O3) -> 13580.24
B4: BOMBEO4_______004 | C4: Bombeo | D4: =SUMIF(Escondida!$B$5:$B$38,Locations!$B4,Escondida!G$5:G$38) -> 1212.9185 | E4: =SUMIF(Escondida!$B$5:$B$38,Locations!$B4,Escondida!H$5:H$38) -> 989.78342 | F4: =SUMIF(Escondida!$B$5:$B$38,Locations!$B4,Escondida!I$5:I$38) -> 1089.6744 | G4: =SUMIF(Escondida!$B$5:$B$38,Locations!$B4,Escondida!J$5:J$38) -> 1267.701 | H4: =SUMIF(Escondida!$B$5:$B$38,Locations!$B4,Escondida!K$5:K$38) -> 1225.1075 | I4: =SUMIF(Escondida!$B$5:$B$38,Locations!$B4,Escondida!L$5:L$38) -> 857.19414 | J4: =SUMIF(Escondida!$B$5:$B$38,Locations!$B4,Escondida!M$5:M$38) -> 1179.9348 | K4: =SUMIF(Escondida!$B$5:$B$38,Locations!$B4,Escondida!N$5:N$38) -> 1199.279 | ... O4: =SUMIF(Escondida!$B$5:$B$38,Locations!$B4,Escondida!R$5:R$38) -> 886.32664 | P4: =SUM(D4:O4) -> 13151.244
B5: CHIMBORAZO____220 | C5: Minera | D5: =SUMIF(Escondida!$B$5:$B$38,Locations!$B5,Escondida!G$5:G$38) -> 27269.015 | E5: =SUMIF(Escondida!$B$5:$B$38,Locations!$B5,Escondida!H$5:H$38) -> 26478.034 | F5: =SUMIF(Escondida!$B$5:$B$38,Locations!$B5,Escondida!I$5:I$38) -> 27638.182 | G5: =SUMIF(Escondida!$B$5:$B$38,Locations!$B5,Escondida!J$5:J$38) -> 28803.39 | H5: =SUMIF(Escondida!$B$5:$B$38,Locations!$B5,Escondida!K$5:K$38) -> 30512.064 | I5: =SUMIF(Escondida!$B$5:$B$38,Locations!$B5,Escondida!L$5:L$38) -> 27099.968 | J5: =SUMIF(Escondida!$B$5:$B$38,Locations!$B5,Escondida!M$5:M$38) -> 25061.936 | K5: =SUMIF(Escondida!$B$5:$B$38,Locations!$B5,Escondida!N$5:N$38) -> 26369.195 | ... O5: =SUMIF(Escondida!$B$5:$B$38,Locations!$B5,Escondida!R$5:R$38) -> 31391.053 | P5: =SUM(D5:O5) -> 331092.7
B6: COLOSO________220 | C6: Desalinacion | D6: =SUMIF(Escondida!$B$5:$B$38,Locations!$B6,Escondida!G$5:G$38) -> 58143.145 | E6: =SUMIF(Escondida!$B$5:$B$38,Locations!$B6,Escondida!H$5:H$38) -> 56262.047 | F6: =SUMIF(Escondida!$B$5:$B$38,Locations!$B6,Escondida!I$5:I$38) -> 60006.624 | G6: =SUMIF(Escondida!$B$5:$B$38,Locations!$B6,Escondida!J$5:J$38) -> 62679.326 | H6: =SUMIF(Escondida!$B$5:$B$38,Locations!$B6,Escondida!K$5:K$38) -> 65148.336 | I6: =SUMIF(Escondida!$B$5:$B$38,Locations!$B6,Escondida!L$5:L$38) -> 57371.327 | J6: =SUMIF(Escondida!$B$5:$B$38,Locations!$B6,Escondida!M$5:M$38) -> 53985.378 | K6: =SUMIF(Escondida!$B$5:$B$38,Locations!$B6,Escondida!N$5:N$38) -> 57250.516 | ... O6: =SUMIF(Escondida!$B$5:$B$38,Locations!$B6,Escondida!R$5:R$38) -> 65415.006 | P6: =SUM(D6:O6) -> 708524.68
B7: DOMEYKO_______220 | C7: Minera | D7: =SUMIF(Escondida!$B$5:$B$38,Locations!$B7,Escondida!G$5:G$38) -> 97903.84 | E7: =SUMIF(Escondida!$B$5:$B$38,Locations!$B7,Escondida!H$5:H$38) -> 89881.523 | F7: =SUMIF(Escondida!$B$5:$B$38,Locations!$B7,Escondida!I$5:I$38) -> 108541.82 | G7: =SUMIF(Escondida!$B$5:$B$38,Locations!$B7,Escondida!J$5:J$38) -> 103268.1 | H7: =SUMIF(Escondida!$B$5:$B$38,Locations!$B7,Escondida!K$5:K$38) -> 114235.92 | I7: =SUMIF(Escondida!$B$5:$B$38,Locations!$B7,Escondida!L$5:L$38) -> 95525.039 | J7: =SUMIF(Escondida!$B$5:$B$38,Locations!$B7,Escondida!M$5:M$38) -> 112482.3 | K7: =SUMIF(Escondida!$B$5:$B$38,Locations!$B7,Escondida!N$5:N$38) -> 112069.56 | ... O7: =SUMIF(Escondida!$B$5:$B$38,Locations!$B7,Escondida!R$5:R$38) -> 102976.76 | P7: =SUM(D7:O7) -> 1241521.7
B8: ESCONDIDA_____220 | C8: Minera | D8: =SUMIF(Escondida!$B$5:$B$38,Locations!$B8,Escondida!G$5:G$38) -> 70180.705 | E8: =SUMIF(Escondida!$B$5:$B$38,Locations!$B8,Escondida!H$5:H$38) -> 69259.806 | F8: =SUMIF(Escondida!$B$5:$B$38,Locations!$B8,Escondida!I$5:I$38) -> 79886.517 | G8: =SUMIF(Escondida!$B$5:$B$38,Locations!$B8,Escondida!J$5:J$38) -> 85001.331 | H8: =SUMIF(Escondida!$B$5:$B$38,Locations!$B8,Escondida!K$5:K$38) -> 77263.231 | I8: =SUMIF(Escondida!$B$5:$B$38,Locations!$B8,Escondida!L$5:L$38) -> 74234.266 | J8: =SUMIF(Escondida!$B$5:$B$38,Locations!$B8,Escondida!M$5:M$38) -> 67198.559 | K8: =SUMIF(Escondida!$B$5:$B$38,Locations!$B8,Escondida!N$5:N$38) -> 74674.386 | ... O8: =SUMIF(Escondida!$B$5:$B$38,Locations!$B8,Escondida!R$5:R$38) -> 81323.3 | P8: =SUM(D8:O8) -> 889249.72
B9: FARELLON______220 | C9: Bombeo | D9: =SUMIF(Escondida!$B$5:$B$38,Locations!$B9,Escondida!G$5:G$38) -> 28037.162 | E9: =SUMIF(Escondida!$B$5:$B$38,Locations!$B9,Escondida!H$5:H$38) -> 27312.761 | F9: =SUMIF(Escondida!$B$5:$B$38,Locations!$B9,Escondida!I$5:I$38) -> 28223.522 | G9: =SUMIF(Escondida!$B$5:$B$38,Locations!$B9,Escondida!J$5:J$38) -> 29696.124 | H9: =SUMIF(Escondida!$B$5:$B$38,Locations!$B9,Escondida!K$5:K$38) -> 31584.449 | I9: =SUMIF(Escondida!$B$5:$B$38,Locations!$B9,Escondida!L$5:L$38) -> 27836.085 | J9: =SUMIF(Escondida!$B$5:$B$38,Locations!$B9,Escondida!M$5:M$38) -> 25511.419 | K9: =SUMIF(Escondida!$B$5:$B$38,Locations!$B9,Escondida!N$5:N$38) -> 26910.52 | ... O9: =SUMIF(Escondida!$B$5:$B$38,Locations!$B9,Escondida!R$5:R$38) -> 31870.647 | P9: =SUM(D9:O9) -> 338849.05
B10: OGP1__________220 | C10: Minera | D10: =SUMIF(Escondida!$B$5:$B$38,Locations!$B10,Escondida!G$5:G$38) -> 86938.798 | E10: =SUMIF(Escondida!$B$5:$B$38,Locations!$B10,Escondida!H$5:H$38) -> 87929.412 | F10: =SUMIF(Escondida!$B$5:$B$38,Locations!$B10,Escondida!I$5:I$38) -> 83848.764 | G10: =SUMIF(Escondida!$B$5:$B$38,Locations!$B10,Escondida!J$5:J$38) -> 99110.904 | H10: =SUMIF(Escondida!$B$5:$B$38,Locations!$B10,Escondida!K$5:K$38) -> 104199.71 | I10: =SUMIF(Escondida!$B$5:$B$38,Locations!$B10,Escondida!L$5:L$38) -> 98548.005 | J10: =SUMIF(Escondida!$B$5:$B$38,Locations!$B10,Escondida!M$5:M$38) -> 102354.04 | K10: =SUMIF(Escondida!$B$5:$B$38,Locations!$B10,Escondida!N$5:N$38) -> 109877.05 | ... O10: =SUMIF(Escondida!$B$5:$B$38,Locations!$B10,Escondida!R$5:R$38) -> 97365.921 | P10: =SUM(D10:O10) -> 1162232.8
B11: PURI__________220 | C11: Bombeo | D11: =SUMIF(Escondida!$B$5:$B$38,Locations!$B11,Escondida!G$5:G$38) -> 28325.414 | E11: =SUMIF(Escondida!$B$5:$B$38,Locations!$B11,Escondida!H$5:H$38) -> 27524.102 | F11: =SUMIF(Escondida!$B$5:$B$38,Locations!$B11,Escondida!I$5:I$38) -> 28685.439 | G11: =SUMIF(Escondida!$B$5:$B$38,Locations!$B11,Escondida!J$5:J$38) -> 29967.123 | H11: =SUMIF(Escondida!$B$5:$B$38,Locations!$B11,Escondida!K$5:K$38) -> 31922.242 | I11: =SUMIF(Escondida!$B$5:$B$38,Locations!$B11,Escondida!L$5:L$38) -> 27966.668 | J11: =SUMIF(Escondida!$B$5:$B$38,Locations!$B11,Escondida!M$5:M$38) -> 26095.733 | K11: =SUMIF(Escondida!$B$5:$B$38,Locations!$B11,Escondida!N$5:N$38) -> 27244.813 | ... O11: =SUMIF(Escondida!$B$5:$B$38,Locations!$B11,Escondida!R$5:R$38) -> 32542.983 | P11: =SUM(D11:O11) -> 343196.92
B12: SULFUROS______220 | C12: Minera | D12: =SUMIF(Escondida!$B$5:$B$38,Locations!$B12,Escondida!G$5:G$38) -> 48095.972 | E12: =SUMIF(Escondida!$B$5:$B$38,Locations!$B12,Escondida!H$5:H$38) -> 43651.651 | F12: =SUMIF(Escondida!$B$5:$B$38,Locations!$B12,Escondida!I$5:I$38) -> 50760.216 | G12: =SUMIF(Escondida!$B$5:$B$38,Locations!$B12,Escondida!J$5:J$38) -> 49048.336 | H12: =SUMIF(Escondida!$B$5:$B$38,Locations!$B12,Escondida!K$5:K$38) -> 50718.681 | I12: =SUMIF(Escondida!$B$5:$B$38,Locations!$B12,Escondida!L$5:L$38) -> 50354.384 | J12: =SUMIF(Escondida!$B$5:$B$38,Locations!$B12,Escondida!M$5:M$38) -> 41932.66 | K12: =SUMIF(Escondida!$B$5:$B$38,Locations!$B12,Escondida!N$5:N$38) -> 43993.938 | ... O12: =SUMIF(Escondida!$B$5:$B$38,Locations!$B12,Escondida!R$5:R$38) -> 51298.537 | P12: =SUM(D12:O12) -> 576054.26
B13: SUR___________110 | C13: no consumo | D13: =SUMIF(Escondida!$B$5:$B$38,Locations!$B13,Escondida!G$5:G$38) -> 0 | E13: =SUMIF(Escondida!$B$5:$B$38,Locations!$B13,Escondida!H$5:H$38) -> 0 | F13: =SUMIF(Escondida!$B$5:$B$38,Locations!$B13,Escondida!I$5:I$38) -> 0 | G13: =SUMIF(Escondida!$B$5:$B$38,Locations!$B13,Escondida!J$5:J$38) -> 0 | H13: =SUMIF(Escondida!$B$5:$B$38,Locations!$B13,Escondida!K$5:K$38) -> 0 | I13: =SUMIF(Escondida!$B$5:$B$38,Locations!$B13,Escondida!L$5:L$38) -> 0 | J13: =SUMIF(Escondida!$B$5:$B$38,Locations!$B13,Escondida!M$5:M$38) -> 0 | K13: =SUMIF(Escondida!$B$5:$B$38,Locations!$B13,Escondida!N$5:N$38) -> 0 | ... O13: =SUMIF(Escondida!$B$5:$B$38,Locations!$B13,Escondida!R$5:R$38) -> 0 | P13: =SUM(D13:O13) -> 0
C15: Tipo | D15: ene-25 | E15: feb-25 | F15: mar-25 | G15: abr-25 | H15: may-25 | I15: jun-25 | J15: jul-25 | K15: ago-25 | L15: sept-25 | M15: oct-25 | N15: nov-25 | O15: dic-25 | P15: TOTAL
C16: Bombeo | D16: =SUMIF($C$2:$C$13,$C16,D$2:D$13) -> 59699.032 | E16: =SUMIF($C$2:$C$13,$C16,E$2:E$13) -> 57637.283 | F16: =SUMIF($C$2:$C$13,$C16,F$2:F$13) -> 59991.375 | G16: =SUMIF($C$2:$C$13,$C16,G$2:G$13) -> 63240.624 | H16: =SUMIF($C$2:$C$13,$C16,H$2:H$13) -> 67124.669 | I16: =SUMIF($C$2:$C$13,$C16,I$2:I$13) -> 58393.099 | J16: =SUMIF($C$2:$C$13,$C16,J$2:J$13) -> 55189.456 | K16: =SUMIF($C$2:$C$13,$C16,K$2:K$13) -> 57858.01 | ... O16: =SUMIF($C$2:$C$13,$C16,O$2:O$13) -> 67199.071 | P16: =SUM(D16:O16) -> 720779.17
C17: Minera | D17: =SUMIF($C$2:$C$13,$C17,D$2:D$13) -> 330388.33 | E17: =SUMIF($C$2:$C$13,$C17,E$2:E$13) -> 317200.42 | F17: =SUMIF($C$2:$C$13,$C17,F$2:F$13) -> 350675.5 | G17: =SUMIF($C$2:$C$13,$C17,G$2:G$13) -> 365232.06 | H17: =SUMIF($C$2:$C$13,$C17,H$2:H$13) -> 376929.61 | I17: =SUMIF($C$2:$C$13,$C17,I$2:I$13) -> 345761.66 | J17: =SUMIF($C$2:$C$13,$C17,J$2:J$13) -> 349029.5 | K17: =SUMIF($C$2:$C$13,$C17,K$2:K$13) -> 366984.13 | ... O17: =SUMIF($C$2:$C$13,$C17,O$2:O$13) -> 364355.57 | P17: =SUM(D17:O17) -> 4200151.2
C18: Desalinacion | D18: =SUMIF($C$2:$C$13,$C18,D$2:D$13) -> 58143.145 | E18: =SUMIF($C$2:$C$13,$C18,E$2:E$13) -> 56262.047 | F18: =SUMIF($C$2:$C$13,$C18,F$2:F$13) -> 60006.624 | G18: =SUMIF($C$2:$C$13,$C18,G$2:G$13) -> 62679.326 | H18: =SUMIF($C$2:$C$13,$C18,H$2:H$13) -> 65148.336 | I18: =SUMIF($C$2:$C$13,$C18,I$2:I$13) -> 57371.327 | J18: =SUMIF($C$2:$C$13,$C18,J$2:J$13) -> 53985.378 | K18: =SUMIF($C$2:$C$13,$C18,K$2:K$13) -> 57250.516 | ... O18: =SUMIF($C$2:$C$13,$C18,O$2:O$13) -> 65415.006 | P18: =SUM(D18:O18) -> 708524.68

Sheet Sources
A2: subestationes | B2: https://mapache.ai/energia/subestaciones
A3: consumo | B3: https://www.coordinador.cl/clienteslibres/
